/Users/yxzuo/anaconda/lib/python3.6/site-packages/h5py/__init__.py:36: FutureWarning: Conversion of the second argument of issubdtype from `float` to `np.floating` is deprecated. In future, it will be treated as `np.float64 == np.dtype(float).type`.
  from ._conv import register_converters as _register_converters
Using TensorFlow backend.
............E........................................./Users/yxzuo/anaconda/lib/python3.6/site-packages/scipy/linalg/basic.py:1226: RuntimeWarning: internal gelsd driver lwork query error, required iwork dimension not returned. This is likely the result of LAPACK bug 0038, fixed in LAPACK 3.2.2 (released July 21, 2010). Falling back to 'gelss' driver.
  warnings.warn(mesg, RuntimeWarning)
/Users/yxzuo/repos/veidt/veidt/model/linear_model.py:78: UserWarning: Feature vectors retrieved from cache and input testing objects ignored. To override the old cache with feature vectors of new testing objects, set override=True.
  warnings.warn("Feature vectors retrieved from cache "
...2018-08-05 18:09:03.708877: I tensorflow/core/platform/cpu_feature_guard.cc:137] Your CPU supports instructions that this TensorFlow binary was not compiled to use: SSE4.2 AVX AVX2 FMA
/Users/yxzuo/anaconda/lib/python3.6/site-packages/sklearn/utils/validation.py:475: DataConversionWarning: Data with input dtype int64 was converted to float64 by StandardScaler.
  warnings.warn(msg, DataConversionWarning)
..EE............SSS......SSS....................
======================================================================
ERROR: test_exclude_similarity_zero (veidt.elsie.tests.test_ensemble.EnsembleRankTest)
----------------------------------------------------------------------
Traceback (most recent call last):
  File "/Users/yxzuo/repos/veidt/veidt/elsie/tests/test_ensemble.py", line 40, in test_exclude_similarity_zero
    self.assertWarnsRegex(UserWarning, r'no overlap .* match'):
  File "/Users/yxzuo/anaconda/lib/python3.6/unittest/case.py", line 230, in __enter__
    for v in sys.modules.values():
RuntimeError: dictionary changed size during iteration

======================================================================
ERROR: test_base_model (veidt.model.tests.test_multi_species_nn.TestMultiSpeciesNN)
----------------------------------------------------------------------
Traceback (most recent call last):
  File "/Users/yxzuo/repos/veidt/veidt/model/tests/test_multi_species_nn.py", line 28, in test_base_model
    model.fit(features, outputs, epochs=100, verbose=0)
  File "/Users/yxzuo/anaconda/lib/python3.6/site-packages/keras/engine/training.py", line 1593, in fit
    batch_size=batch_size)
  File "/Users/yxzuo/anaconda/lib/python3.6/site-packages/keras/engine/training.py", line 1430, in _standardize_user_data
    exception_prefix='target')
  File "/Users/yxzuo/anaconda/lib/python3.6/site-packages/keras/engine/training.py", line 70, in _standardize_input_data
    data = [np.expand_dims(x, 1) if x is not None and x.ndim == 1 else x for x in data]
  File "/Users/yxzuo/anaconda/lib/python3.6/site-packages/keras/engine/training.py", line 70, in <listcomp>
    data = [np.expand_dims(x, 1) if x is not None and x.ndim == 1 else x for x in data]
AttributeError: 'float' object has no attribute 'ndim'

======================================================================
ERROR: test_create_atomic_nn (veidt.model.tests.test_multi_species_nn.TestMultiSpeciesNN)
----------------------------------------------------------------------
Traceback (most recent call last):
  File "/Users/yxzuo/repos/veidt/veidt/model/tests/test_multi_species_nn.py", line 17, in test_create_atomic_nn
    model.fit(x, y, epochs=100, verbose=False)
  File "/Users/yxzuo/anaconda/lib/python3.6/site-packages/keras/engine/training.py", line 1593, in fit
    batch_size=batch_size)
  File "/Users/yxzuo/anaconda/lib/python3.6/site-packages/keras/engine/training.py", line 1430, in _standardize_user_data
    exception_prefix='target')
  File "/Users/yxzuo/anaconda/lib/python3.6/site-packages/keras/engine/training.py", line 70, in _standardize_input_data
    data = [np.expand_dims(x, 1) if x is not None and x.ndim == 1 else x for x in data]
  File "/Users/yxzuo/anaconda/lib/python3.6/site-packages/keras/engine/training.py", line 70, in <listcomp>
    data = [np.expand_dims(x, 1) if x is not None and x.ndim == 1 else x for x in data]
AttributeError: 'float' object has no attribute 'ndim'

----------------------------------------------------------------------
Ran 105 tests in 44.039s

FAILED (SKIP=6, errors=3)
